Workbook

Sheet Indicators
A1: DATES | B1: GDP | C1: CPI | D1: REPO RATE | E1: INDIA VIX | F1: VIX CHANGE | G1: GOLD/NIFTY | H1: NIFTY PE RATIO | I1: USD/INR % CHANGE | J1: OIL % CHANGE | K1: Net FII (cr)
A2: 41730 | B2: 5.7 | C2: 8.4586466 | D2: 8 | E2: 30.5925 | F2: 41.48 | G2: =Assets!I2/Assets!B2 -> 3.7429771 | H2: 18.8 | I2: 0.0056 | J2: 0.0029 | K2: 418
A3: 41760 | B3: 5.7 | C3: 8.2089552 | D3: 8 | E3: 16.335 | F3: -46.6 | G3: =Assets!I3/Assets!B3 -> 3.3001064 | H3: 19.8 | I3: -0.0192 | J3: 0.0056 | K3: 33778
A4: 41791 | B4: 5.7 | C4: 7.4380165 | D4: 8 | E4: 17.8725 | F4: 9.41 | G4: =Assets!I4/Assets!B4 -> 3.3302023 | H4: 20.7 | I4: 0.0146 | J4: 0.0312 | K4: 30705
A5: 41821 | B5: 5.3 | C5: 7.9494128 | D5: 8 | E5: 13.8225 | F5: -22.66 | G5: =Assets!I5/Assets!B5 -> 3.2650078 | H5: 20.6 | I5: 0.0084 | J5: -0.0494 | K5: 36045
A6: 41852 | B6: 5.3 | C6: 7.6717217 | D6: 8 | E6: 13.0675 | F6: -5.46 | G6: =Assets!I6/Assets!B6 -> 3.1443714 | H6: 20.8 | I6: -0.0007 | J6: -0.0259 | K6: 22135
A7: 41883 | B7: 5.3 | C7: 5.8669002 | D7: 8 | E7: 13.145 | F7: 0.59 | G7: =Assets!I7/Assets!B7 -> 3.0245951 | H7: 20.8 | I7: 0.0235 | J7: -0.0814 | K7: 20973
A8: 41913 | B8: 7.5 | C8: 4.7619048 | D8: 8 | E8: 13.295 | F8: 1.14 | G8: =Assets!I8/Assets!B8 -> 2.782536 | H8: 21.6 | I8: -0.0086 | J8: -0.0942 | K8: 16729
A9: 41944 | B9: 7.5 | C9: 3.1516184 | D9: 8 | E9: 12.8975 | F9: -2.99 | G9: =Assets!I9/Assets!B9 -> 2.7578878 | H9: 21.9 | I9: 0.0131 | J9: -0.1825 | K9: 25479
A10: 41974 | B10: 7.5 | C10: 4.1558442 | D10: 8 | E10: 15.12 | F10: 17.23 | G10: =Assets!I10/Assets!B10 -> 2.9341063 | H10: 21.2 | I10: 0.0134 | J10: -0.1753 | K10: 12225
A11: 42005 | B11: 7.5 | C11: 5.3415061 | D11: 8 | E11: 20.1725 | F11: 33.42 | G11: =Assets!I11/Assets!B11 -> 2.8596049 | H11: 22.5 | I11: -0.0162 | J11: -0.0732 | K11: 33687
A12: 42036 | B12: 7.5 | C12: 5.7894737 | D12: 7.75 | E12: 16.97 | F12: -15.88 | G12: =Assets!I12/Assets!B12 -> 2.6830178 | H12: 23.8 | I12: -0.0058 | J12: 0.1705 | K12: 24564
A13: 42064 | B13: 7.5 | C13: 5.6719023 | D13: 7.75 | E13: 14.4925 | F13: -14.6 | G13: =Assets!I13/Assets!B13 -> 2.7809511 | H13: 22.7 | I13: 0.0103 | J13: -0.1099 | K13: 20725
A14: 42095 | B14: 7 | C14: =[1]CPI!D14 -> 4.8653345 | D14: 7.5 | E14: 17.225 | F14: 18.85 | G14: =Assets!I14/Assets!B14 -> 3.0060969 | H14: 22.1 | I14: 0.0199 | J14: 0.2 | K14: 15331
A15: 42125 | B15: 7 | C15: =[1]CPI!D15 -> 5.0086356 | D15: 7.5 | E15: 16.6575 | F15: -3.29 | G15: =Assets!I15/Assets!B15 -> 2.8907697 | H15: 23.1 | I15: 0.0034 | J15: -0.0194 | K15: -14272
A16: 42156 | B16: 7 | C16: =[1]CPI!D16 -> 5.3984576 | D16: 7.5 | E16: 16.9275 | F16: 1.62 | G16: =Assets!I16/Assets!B16 -> 2.8629433 | H16: 23.2 | I16: -0.0022 | J16: -0.0302 | K16: -1607
A17: 42186 | B17: 7.4 | C17: =[1]CPI!D17 -> 3.6912752 | D17: 7.25 | E17: 14.57 | F17: -13.93 | G17: =Assets!I17/Assets!B17 -> 2.639861 | H17: 23.5 | I17: 0.006 | J17: -0.176 | K17: 5323
A18: 42217 | B18: 7.4 | C18: =[1]CPI!D18 -> 3.7406484 | D18: 7.25 | E18: 24.595 | F18: 68.81 | G18: =Assets!I18/Assets!B18 -> 3.0330597 | H18: 22.1 | I18: 0.0379 | J18: 0.0405 | K18: -17524
A19: 42248 | B19: 7.4 | C19: =[1]CPI!D19 -> 4.4129892 | D19: 7.25 | E19: 19.625 | F19: -20.21 | G19: =Assets!I19/Assets!B19 -> 2.9547734 | H19: 22.2 | I19: -0.0135 | J19: -0.108 | K19: -5787
A20: 42278 | B20: 7.3 | C20: =[1]CPI!D20 -> 4.9958368 | D20: 6.75 | E20: 17.88 | F20: -8.89 | G20: =Assets!I20/Assets!B20 -> 2.9760843 | H20: 22.1 | I20: -0.0014 | J20: 0.0257 | K20: 22352
A21: 42309 | B21: 7.3 | C21: =[1]CPI!D21 -> 5.4121565 | D21: 6.75 | E21: 16.43 | F21: -8.11 | G21: =Assets!I21/Assets!B21 -> 2.8682045 | H21: 21.5 | I21: 0.0159 | J21: -0.1008 | K21: -10828
A22: 42339 | B22: 7.3 | C22: =[1]CPI!D22 -> 5.6113903 | D22: 6.75 | E22: 13.87 | F22: -15.58 | G22: =Assets!I22/Assets!B22 -> 2.8395905 | H22: 21.5 | I22: -0.0038 | J22: -0.1673 | K22: -8307
A23: 42370 | B23: 7.9 | C23: =[1]CPI!D23 -> 5.6903766 | D23: 6.75 | E23: 17.24 | F23: 24.3 | G23: =Assets!I23/Assets!B23 -> 3.2206975 | H23: 20.2 | I23: 0.0252 | J23: -0.0446 | K23: -8814
A24: 42401 | B24: 7.9 | C24: =[1]CPI!D24 -> 5.2631579 | D24: 6.75 | E24: 20.1575 | F24: 16.92 | G24: =Assets!I24/Assets!B24 -> 3.8736862 | H24: 18.9 | I24: 0.0049 | J24: 0.0161 | K24: -13716
A25: 42430 | B25: 7.9 | C25: =[1]CPI!D25 -> 4.8252912 | D25: 6.75 | E25: 16.5825 | F25: -17.74 | G25: =Assets!I25/Assets!B25 -> 3.4009743 | H25: 20.9 | I25: -0.0286 | J25: 0.1028 | K25: 19665
... A121: 45352 | B121: 7.8 | C121: =[1]CPI!D121 -> 4.8532731 | D121: 6.5 | E121: 12.8325 | F121: -17.6 | G121: =Assets!I121/Assets!B121 -> 2.6784065 | H121: 22.9 | I121: 0.0054 | J121: 0.0621 | K121: 51996

Sheet Assets
A1: DATE | B1: NIFTY 50 | C1: % CHANGE | D1: NIFTY BANK | E1: % CHANGE2 | F1: NIFTY IT | G1: % CHANGE3 | H1: GOLD usd | I1: GOLD/10gram inr | J1: % CHANGE4 | K1: 10Y G-SEC | L1: % CHANGE5 | M1: USD/INR | N1: % CHANGE6
A2: 41730 | B2: 6696.4 | C2: -0.0012 | D2: 12855.85 | E2: 0.0089 | F2: 9227.95 | G2: -0.0075 | H2: 1292 | I2: =(H2/31.1035)*10*M2 -> 25064.472 | J2: 0.029 | K2: 8.828 | L2: 0.0027 | M2: 60.34 | N2: 0.0056
A3: 41760 | B3: 7229.95 | C3: 0.0797 | D3: 14793.4 | E3: 0.1507 | F3: 8970.3 | G3: -0.0279 | H3: 1254 | I3: =(H3/31.1035)*10*M3 -> 23859.604 | J3: -0.1054 | K3: 8.645 | L3: -0.0207 | M3: 59.18 | N3: -0.0192
A4: 41791 | B4: 7611.35 | C4: 0.0528 | D4: 15241.9 | E4: 0.0303 | F4: 9912.3 | G4: 0.105 | H4: 1313 | I4: =(H4/31.1035)*10*M4 -> 25347.336 | J4: 0.046 | K4: 8.744 | L4: 0.0115 | M4: 60.045 | N4: 0.0146
A5: 41821 | B5: 7721.3 | C5: 0.0144 | D5: 15267.6 | E5: 0.0017 | F5: 10304.7 | G5: 0.0396 | H5: 1295 | I5: =(H5/31.1035)*10*M5 -> 25210.105 | J5: -0.0144 | K5: 8.718 | L5: -0.003 | M5: 60.55 | N5: 0.0084
A6: 41852 | B6: 7954.35 | C6: 0.0302 | D6: 15740.4 | E6: 0.031 | F6: 10679.65 | G6: 0.0364 | H6: 1285.75 | I6: =(H6/31.1035)*10*M6 -> 25011.431 | J6: 0.0006 | K6: 8.559 | L6: -0.0182 | M6: 60.505 | N6: -0.0007
A7: 41883 | B7: 7964.8 | C7: 0.0013 | D7: 15392.25 | E7: -0.0221 | F7: 11302.7 | G7: 0.0583 | H7: 1210 | I7: =(H7/31.1035)*10*M7 -> 24090.295 | J7: -0.0393 | K7: 8.511 | L7: -0.0056 | M7: 61.925 | N7: 0.0235
A8: 41913 | B8: 8322.2 | C8: 0.0449 | D8: 17045.05 | E8: 0.1074 | F8: 11341.05 | G8: 0.0034 | H8: 1173.25 | I8: =(H8/31.1035)*10*M8 -> 23156.821 | J8: -0.0173 | K8: 8.278 | L8: -0.0274 | M8: 61.39 | N8: -0.0086
A9: 41944 | B9: 8588.25 | C9: 0.032 | D9: 18513.15 | E9: 0.0861 | F9: 11898.05 | G9: 0.0491 | H9: 1184.5 | I9: =(H9/31.1035)*10*M9 -> 23685.43 | J9: 0.0066 | K9: 8.087 | L9: -0.0231 | M9: 62.195 | N9: 0.0131
A10: 41974 | B10: 8282.7 | C10: -0.0356 | D10: 18736.65 | E10: 0.0121 | F10: 11216.3 | G10: -0.0573 | H10: 1199.25 | I10: =(H10/31.1035)*10*M10 -> 24302.322 | J10: 0.0087 | K10: 7.855 | L10: -0.0287 | M10: 63.03 | N10: 0.0134
A11: 42005 | B11: 8808.9 | C11: 0.0635 | D11: 19843.75 | E11: 0.0591 | F11: 11824.75 | G11: 0.0542 | H11: 1263.5 | I11: =(H11/31.1035)*10*M11 -> 25189.974 | J11: 0.0465 | K11: 7.691 | L11: -0.0209 | M11: 62.01 | N11: -0.0162
A12: 42036 | B12: 8901.85 | C12: 0.0106 | D12: 19691.2 | E12: -0.0077 | F12: 12659.8 | G12: 0.0706 | H12: 1205 | I12: =(H12/31.1035)*10*M12 -> 23883.822 | J12: -0.0538 | K12: 7.724 | L12: 0.0043 | M12: 61.649 | N12: -0.0058
A13: 42064 | B13: 8491 | C13: -0.0462 | D13: 18206.65 | E13: -0.0754 | F13: 12083 | G13: -0.0456 | H13: 1179.25 | I13: =(H13/31.1035)*10*M13 -> 23613.056 | J13: -0.0169 | K13: 7.738 | L13: 0.0018 | M13: 62.281 | N13: 0.0103
... A121: 45352 | B121: 22326.9 | C121: 0.0157 | D121: 47124.6 | E121: 0.0218 | F121: 34898.15 | G121: -0.0748 | H121: 2231.56 | I121: =(H121/31.1035)*10*M121 -> 59800.513 | J121: 0.0726 | K121: 7.052 | L121: -0.0037 | M121: 83.35 | N121: 0.0054

Sheet Normalisation
A1: INDICATORS | B1: DIRECTION | C1: FORMULA | E1: DATES | F1: GDP | G1: CPI | H1: REPO RATE | I1: INDIA VIX | J1: GOLD/NIFTY | K1: NIFTY PE RATIO | L1: USD/INR % CHANGE | M1: OIL % CHANGE | N1: Net FII (cr)
A2: GDP | B2: ⬇️ High GDP = Low Risk | C2: INVERSE | E2: 41760 | F2: =MAX(0,MIN(10,(PERCENTILE(Indicators!$K$2:$K$121,0.95)-Table1[[#This Row],[Net FII (cr)]])/(PERCENTILE(Indicators!$K$2:$K$121,0.95)-PERCENTILE(Indicators!$K$2:$K$121,0.05))*10)) -> 5.832029 | G2: =MAX(0,MIN(10,(Indicators!C3-PERCENTILE(Indicators!$C:$C,0.05))/(PERCENTILE(Indicators!$C:$C,0.95)-PERCENTILE(Indicators!$C:$C,0.05))*10)) -> 10 | H2: =MAX(0,MIN(10,(Indicators!D3-PERCENTILE(Indicators!$D:$D,0.05))/(PERCENTILE(Indicators!$D:$D,0.95)-PERCENTILE(Indicators!$D:$D,0.05))*10)) -> 10 | I2: =MAX(0,MIN(10,(Table1[[#This Row],[INDIA VIX]]-PERCENTILE(Indicators!$E$2:$E$121,0.05))/(PERCENTILE(Indicators!$E$2:$E$121,0.95)-PERCENTILE(Indicators!$E$2:$E$121,0.05))*10)) -> 10 | J2: =MAX(0,MIN(10,(Indicators!G3-PERCENTILE(Indicators!$G:$G,0.05))/(PERCENTILE(Indicators!$G:$G,0.95)-PERCENTILE(Indicators!$G:$G,0.05))*10)) -> 5.5363334 | K2: =MAX(0,MIN(10,(Indicators!H3-PERCENTILE(Indicators!$H:$H,0.05))/(PERCENTILE(Indicators!$H:$H,0.95)-PERCENTILE(Indicators!$H:$H,0.05))*10)) -> 0 | L2: =MAX(0,MIN(10,(Indicators!I3-PERCENTILE(Indicators!$I:$I,0.05))/(PERCENTILE(Indicators!$I:$I,0.95)-PERCENTILE(Indicators!$I:$I,0.05))*10)) -> 0.017853158 | M2: =MAX(0,MIN(10,(Indicators!J3-PERCENTILE(Indicators!$J:$J,0.05))/(PERCENTILE(Indicators!$J:$J,0.95)-PERCENTILE(Indicators!$J:$J,0.05))*10)) -> 5.3717316 | N2: =MAX(0,MIN(10,(PERCENTILE(Indicators!$K$2:$K$121,0.95)-Table1[[#This Row],[Net FII (cr)]])/(PERCENTILE(Indicators!$K$2:$K$121,0.95)-PERCENTILE(Indicators!$K$2:$K$121,0.05))*10)) -> 5.832029
A3: CPI | B3: ⬆️ High CPI = High Risk | C3: NORMAL | E3: 41791 | F3: =MAX(0,MIN(10,(PERCENTILE(Indicators!$K$2:$K$121,0.95)-Table1[[#This Row],[Net FII (cr)]])/(PERCENTILE(Indicators!$K$2:$K$121,0.95)-PERCENTILE(Indicators!$K$2:$K$121,0.05))*10)) -> 2.0754668 | G3: =MAX(0,MIN(10,(Indicators!C4-PERCENTILE(Indicators!$C:$C,0.05))/(PERCENTILE(Indicators!$C:$C,0.95)-PERCENTILE(Indicators!$C:$C,0.05))*10)) -> 9.6905803 | H3: =MAX(0,MIN(10,(Indicators!D4-PERCENTILE(Indicators!$D:$D,0.05))/(PERCENTILE(Indicators!$D:$D,0.95)-PERCENTILE(Indicators!$D:$D,0.05))*10)) -> 10 | I3: =MAX(0,MIN(10,(Table1[[#This Row],[INDIA VIX]]-PERCENTILE(Indicators!$E$2:$E$121,0.05))/(PERCENTILE(Indicators!$E$2:$E$121,0.95)-PERCENTILE(Indicators!$E$2:$E$121,0.05))*10)) -> 2.8024674 | J3: =MAX(0,MIN(10,(Indicators!G4-PERCENTILE(Indicators!$G:$G,0.05))/(PERCENTILE(Indicators!$G:$G,0.95)-PERCENTILE(Indicators!$G:$G,0.05))*10)) -> 5.7319258 | K3: =MAX(0,MIN(10,(Indicators!H4-PERCENTILE(Indicators!$H:$H,0.05))/(PERCENTILE(Indicators!$H:$H,0.95)-PERCENTILE(Indicators!$H:$H,0.05))*10)) -> 0.25984912 | L3: =MAX(0,MIN(10,(Indicators!I4-PERCENTILE(Indicators!$I:$I,0.05))/(PERCENTILE(Indicators!$I:$I,0.95)-PERCENTILE(Indicators!$I:$I,0.05))*10)) -> 7.5608123 | M3: =MAX(0,MIN(10,(Indicators!J4-PERCENTILE(Indicators!$J:$J,0.05))/(PERCENTILE(Indicators!$J:$J,0.95)-PERCENTILE(Indicators!$J:$J,0.05))*10)) -> 6.1657517 | N3: =MAX(0,MIN(10,(PERCENTILE(Indicators!$K$2:$K$121,0.95)-Table1[[#This Row],[Net FII (cr)]])/(PERCENTILE(Indicators!$K$2:$K$121,0.95)-PERCENTILE(Indicators!$K$2:$K$121,0.05))*10)) -> 2.0754668
A4: REPO RATE | B4: ⬆️ High Rate = High Risk | C4: NORMAL | E4: 41821 | F4: =MAX(0,MIN(10,(PERCENTILE(Indicators!$K$2:$K$121,0.95)-Table1[[#This Row],[Net FII (cr)]])/(PERCENTILE(Indicators!$K$2:$K$121,0.95)-PERCENTILE(Indicators!$K$2:$K$121,0.05))*10)) -> 2.4215074 | G4: =MAX(0,MIN(10,(Indicators!C5-PERCENTILE(Indicators!$C:$C,0.05))/(PERCENTILE(Indicators!$C:$C,0.95)-PERCENTILE(Indicators!$C:$C,0.05))*10)) -> 10 | H4: =MAX(0,MIN(10,(Indicators!D5-PERCENTILE(Indicators!$D:$D,0.05))/(PERCENTILE(Indicators!$D:$D,0.95)-PERCENTILE(Indicators!$D:$D,0.05))*10)) -> 10 | I4: =MAX(0,MIN(10,(Table1[[#This Row],[INDIA VIX]]-PERCENTILE(Indicators!$E$2:$E$121,0.05))/(PERCENTILE(Indicators!$E$2:$E$121,0.95)-PERCENTILE(Indicators!$E$2:$E$121,0.05))*10)) -> 3.7379922 | J4: =MAX(0,MIN(10,(Indicators!G5-PERCENTILE(Indicators!$G:$G,0.05))/(PERCENTILE(Indicators!$G:$G,0.95)-PERCENTILE(Indicators!$G:$G,0.05))*10)) -> 5.3082292 | K4: =MAX(0,MIN(10,(Indicators!H5-PERCENTILE(Indicators!$H:$H,0.05))/(PERCENTILE(Indicators!$H:$H,0.95)-PERCENTILE(Indicators!$H:$H,0.05))*10)) -> 0.17602682 | L4: =MAX(0,MIN(10,(Indicators!I5-PERCENTILE(Indicators!$I:$I,0.05))/(PERCENTILE(Indicators!$I:$I,0.95)-PERCENTILE(Indicators!$I:$I,0.05))*10)) -> 6.1771926 | M4: =MAX(0,MIN(10,(Indicators!J5-PERCENTILE(Indicators!$J:$J,0.05))/(PERCENTILE(Indicators!$J:$J,0.95)-PERCENTILE(Indicators!$J:$J,0.05))*10)) -> 3.6658292 | N4: =MAX(0,MIN(10,(PERCENTILE(Indicators!$K$2:$K$121,0.95)-Table1[[#This Row],[Net FII (cr)]])/(PERCENTILE(Indicators!$K$2:$K$121,0.95)-PERCENTILE(Indicators!$K$2:$K$121,0.05))*10)) -> 2.4215074
A5: INDIA VIX | B5: ⬆️ High VIX = High Risk | C5: NORMAL | E5: 41852 | F5: =MAX(0,MIN(10,(PERCENTILE(Indicators!$K$2:$K$121,0.95)-Table1[[#This Row],[Net FII (cr)]])/(PERCENTILE(Indicators!$K$2:$K$121,0.95)-PERCENTILE(Indicators!$K$2:$K$121,0.05))*10)) -> 1.8201872 | G5: =MAX(0,MIN(10,(Indicators!C6-PERCENTILE(Indicators!$C:$C,0.05))/(PERCENTILE(Indicators!$C:$C,0.95)-PERCENTILE(Indicators!$C:$C,0.05))*10)) -> 10 | H5: =MAX(0,MIN(10,(Indicators!D6-PERCENTILE(Indicators!$D:$D,0.05))/(PERCENTILE(Indicators!$D:$D,0.95)-PERCENTILE(Indicators!$D:$D,0.05))*10)) -> 10 | I5: =MAX(0,MIN(10,(Table1[[#This Row],[INDIA VIX]]-PERCENTILE(Indicators!$E$2:$E$121,0.05))/(PERCENTILE(Indicators!$E$2:$E$121,0.95)-PERCENTILE(Indicators!$E$2:$E$121,0.05))*10)) -> 1.2736828 | J5: =MAX(0,MIN(10,(Indicators!G6-PERCENTILE(Indicators!$G:$G,0.05))/(PERCENTILE(Indicators!$G:$G,0.95)-PERCENTILE(Indicators!$G:$G,0.05))*10)) -> 4.5242178 | K5: =MAX(0,MIN(10,(Indicators!H6-PERCENTILE(Indicators!$H:$H,0.05))/(PERCENTILE(Indicators!$H:$H,0.95)-PERCENTILE(Indicators!$H:$H,0.05))*10)) -> 0.34367142 | L5: =MAX(0,MIN(10,(Indicators!I6-PERCENTILE(Indicators!$I:$I,0.05))/(PERCENTILE(Indicators!$I:$I,0.95)-PERCENTILE(Indicators!$I:$I,0.05))*10)) -> 4.1463959 | M5: =MAX(0,MIN(10,(Indicators!J6-PERCENTILE(Indicators!$J:$J,0.05))/(PERCENTILE(Indicators!$J:$J,0.95)-PERCENTILE(Indicators!$J:$J,0.05))*10)) -> 4.3947148 | N5: =MAX(0,MIN(10,(PERCENTILE(Indicators!$K$2:$K$121,0.95)-Table1[[#This Row],[Net FII (cr)]])/(PERCENTILE(Indicators!$K$2:$K$121,0.95)-PERCENTILE(Indicators!$K$2:$K$121,0.05))*10)) -> 1.8201872
A6: GOLD/NIFTY | B6: ⬆️ High Ratio = High Risk | C6: NORMAL | E6: 41883 | F6: =MAX(0,MIN(10,(PERCENTILE(Indicators!$K$2:$K$121,0.95)-Table1[[#This Row],[Net FII (cr)]])/(PERCENTILE(Indicators!$K$2:$K$121,0.95)-PERCENTILE(Indicators!$K$2:$K$121,0.05))*10)) -> 3.3865475 | G6: =MAX(0,MIN(10,(Indicators!C7-PERCENTILE(Indicators!$C:$C,0.05))/(PERCENTILE(Indicators!$C:$C,0.95)-PERCENTILE(Indicators!$C:$C,0.05))*10)) -> 6.5720411 | H6: =MAX(0,MIN(10,(Indicators!D7-PERCENTILE(Indicators!$D:$D,0.05))/(PERCENTILE(Indicators!$D:$D,0.95)-PERCENTILE(Indicators!$D:$D,0.05))*10)) -> 10 | I6: =MAX(0,MIN(10,(Table1[[#This Row],[INDIA VIX]]-PERCENTILE(Indicators!$E$2:$E$121,0.05))/(PERCENTILE(Indicators!$E$2:$E$121,0.95)-PERCENTILE(Indicators!$E$2:$E$121,0.05))*10)) -> 0.81428691 | J6: =MAX(0,MIN(10,(Indicators!G7-PERCENTILE(Indicators!$G:$G,0.05))/(PERCENTILE(Indicators!$G:$G,0.95)-PERCENTILE(Indicators!$G:$G,0.05))*10)) -> 3.7457962 | K6: =MAX(0,MIN(10,(Indicators!H7-PERCENTILE(Indicators!$H:$H,0.05))/(PERCENTILE(Indicators!$H:$H,0.95)-PERCENTILE(Indicators!$H:$H,0.05))*10)) -> 0.34367142 | L6: =MAX(0,MIN(10,(Indicators!I7-PERCENTILE(Indicators!$I:$I,0.05))/(PERCENTILE(Indicators!$I:$I,0.95)-PERCENTILE(Indicators!$I:$I,0.05))*10)) -> 9.5469761 | M6: =MAX(0,MIN(10,(Indicators!J7-PERCENTILE(Indicators!$J:$J,0.05))/(PERCENTILE(Indicators!$J:$J,0.95)-PERCENTILE(Indicators!$J:$J,0.05))*10)) -> 2.6733042 | N6: =MAX(0,MIN(10,(PERCENTILE(Indicators!$K$2:$K$121,0.95)-Table1[[#This Row],[Net FII (cr)]])/(PERCENTILE(Indicators!$K$2:$K$121,0.95)-PERCENTILE(Indicators!$K$2:$K$121,0.05))*10)) -> 3.3865475
A7: NIFTY PE RATIO | B7: ⬆️ High PE = High Risk | C7: NORMAL | E7: 41913 | F7: =MAX(0,MIN(10,(PERCENTILE(Indicators!$K$2:$K$121,0.95)-Table1[[#This Row],[Net FII (cr)]])/(PERCENTILE(Indicators!$K$2:$K$121,0.95)-PERCENTILE(Indicators!$K$2:$K$121,0.05))*10)) -> 3.5173966 | G7: =MAX(0,MIN(10,(Indicators!C8-PERCENTILE(Indicators!$C:$C,0.05))/(PERCENTILE(Indicators!$C:$C,0.95)-PERCENTILE(Indicators!$C:$C,0.05))*10)) -> 4.3787144 | H7: =MAX(0,MIN(10,(Indicators!D8-PERCENTILE(Indicators!$D:$D,0.05))/(PERCENTILE(Indicators!$D:$D,0.95)-PERCENTILE(Indicators!$D:$D,0.05))*10)) -> 10 | I7: =MAX(0,MIN(10,(Table1[[#This Row],[INDIA VIX]]-PERCENTILE(Indicators!$E$2:$E$121,0.05))/(PERCENTILE(Indicators!$E$2:$E$121,0.95)-PERCENTILE(Indicators!$E$2:$E$121,0.05))*10)) -> 0.86144345 | J7: =MAX(0,MIN(10,(Indicators!G8-PERCENTILE(Indicators!$G:$G,0.05))/(PERCENTILE(Indicators!$G:$G,0.95)-PERCENTILE(Indicators!$G:$G,0.05))*10)) -> 2.1726629 | K7: =MAX(0,MIN(10,(Indicators!H8-PERCENTILE(Indicators!$H:$H,0.05))/(PERCENTILE(Indicators!$H:$H,0.95)-PERCENTILE(Indicators!$H:$H,0.05))*10)) -> 1.0142498 | L7: =MAX(0,MIN(10,(Indicators!I8-PERCENTILE(Indicators!$I:$I,0.05))/(PERCENTILE(Indicators!$I:$I,0.95)-PERCENTILE(Indicators!$I:$I,0.05))*10)) -> 2.3833966 | M7: =MAX(0,MIN(10,(Indicators!J8-PERCENTILE(Indicators!$J:$J,0.05))/(PERCENTILE(Indicators!$J:$J,0.95)-PERCENTILE(Indicators!$J:$J,0.05))*10)) -> 2.2762942 | N7: =MAX(0,MIN(10,(PERCENTILE(Indicators!$K$2:$K$121,0.95)-Table1[[#This Row],[Net FII (cr)]])/(PERCENTILE(Indicators!$K$2:$K$121,0.95)-PERCENTILE(Indicators!$K$2:$K$121,0.05))*10)) -> 3.5173966
A8: USD/INR % CHANGE | B8: ⬆️ High Change = High Risk | C8: NORMAL | E8: 41944 | F8: =MAX(0,MIN(10,(PERCENTILE(Indicators!$K$2:$K$121,0.95)-Table1[[#This Row],[Net FII (cr)]])/(PERCENTILE(Indicators!$K$2:$K$121,0.95)-PERCENTILE(Indicators!$K$2:$K$121,0.05))*10)) -> 3.9952998 | G8: =MAX(0,MIN(10,(Indicators!C9-PERCENTILE(Indicators!$C:$C,0.05))/(PERCENTILE(Indicators!$C:$C,0.95)-PERCENTILE(Indicators!$C:$C,0.05))*10)) -> 1.1824259 | H8: =MAX(0,MIN(10,(Indicators!D9-PERCENTILE(Indicators!$D:$D,0.05))/(PERCENTILE(Indicators!$D:$D,0.95)-PERCENTILE(Indicators!$D:$D,0.05))*10)) -> 10 | I8: =MAX(0,MIN(10,(Table1[[#This Row],[INDIA VIX]]-PERCENTILE(Indicators!$E$2:$E$121,0.05))/(PERCENTILE(Indicators!$E$2:$E$121,0.95)-PERCENTILE(Indicators!$E$2:$E$121,0.05))*10)) -> 0.95271416 | J8: =MAX(0,MIN(10,(Indicators!G9-PERCENTILE(Indicators!$G:$G,0.05))/(PERCENTILE(Indicators!$G:$G,0.95)-PERCENTILE(Indicators!$G:$G,0.05))*10)) -> 2.0124756 | K8: =MAX(0,MIN(10,(Indicators!H9-PERCENTILE(Indicators!$H:$H,0.05))/(PERCENTILE(Indicators!$H:$H,0.95)-PERCENTILE(Indicators!$H:$H,0.05))*10)) -> 1.2657167 | L8: =MAX(0,MIN(10,(Indicators!I9-PERCENTILE(Indicators!$I:$I,0.05))/(PERCENTILE(Indicators!$I:$I,0.95)-PERCENTILE(Indicators!$I:$I,0.05))*10)) -> 7.2260656 | M8: =MAX(0,MIN(10,(Indicators!J9-PERCENTILE(Indicators!$J:$J,0.05))/(PERCENTILE(Indicators!$J:$J,0.95)-PERCENTILE(Indicators!$J:$J,0.05))*10)) -> 0 | N8: =MAX(0,MIN(10,(PERCENTILE(Indicators!$K$2:$K$121,0.95)-Table1[[#This Row],[Net FII (cr)]])/(PERCENTILE(Indicators!$K$2:$K$121,0.95)-PERCENTILE(Indicators!$K$2:$K$121,0.05))*10)) -> 3.9952998
A9: OIL % CHANGE | B9: ⬆️ High Change = High Risk | C9: NORMAL | E9: 41974 | F9: =MAX(0,MIN(10,(PERCENTILE(Indicators!$K$2:$K$121,0.95)-Table1[[#This Row],[Net FII (cr)]])/(PERCENTILE(Indicators!$K$2:$K$121,0.95)-PERCENTILE(Indicators!$K$2:$K$121,0.05))*10)) -> 3.0099905 | G9: =MAX(0,MIN(10,(Indicators!C10-PERCENTILE(Indicators!$C:$C,0.05))/(PERCENTILE(Indicators!$C:$C,0.95)-PERCENTILE(Indicators!$C:$C,0.05))*10)) -> 3.175733 | H9: =MAX(0,MIN(10,(Indicators!D10-PERCENTILE(Indicators!$D:$D,0.05))/(PERCENTILE(Indicators!$D:$D,0.95)-PERCENTILE(Indicators!$D:$D,0.05))*10)) -> 10 | I9: =MAX(0,MIN(10,(Table1[[#This Row],[INDIA VIX]]-PERCENTILE(Indicators!$E$2:$E$121,0.05))/(PERCENTILE(Indicators!$E$2:$E$121,0.95)-PERCENTILE(Indicators!$E$2:$E$121,0.05))*10)) -> 0.71084676 | J9: =MAX(0,MIN(10,(Indicators!G10-PERCENTILE(Indicators!$G:$G,0.05))/(PERCENTILE(Indicators!$G:$G,0.95)-PERCENTILE(Indicators!$G:$G,0.05))*10)) -> 3.1577126 | K9: =MAX(0,MIN(10,(Indicators!H10-PERCENTILE(Indicators!$H:$H,0.05))/(PERCENTILE(Indicators!$H:$H,0.95)-PERCENTILE(Indicators!$H:$H,0.05))*10)) -> 0.6789606 | L9: =MAX(0,MIN(10,(Indicators!I10-PERCENTILE(Indicators!$I:$I,0.05))/(PERCENTILE(Indicators!$I:$I,0.95)-PERCENTILE(Indicators!$I:$I,0.05))*10)) -> 7.293015 | M9: =MAX(0,MIN(10,(Indicators!J10-PERCENTILE(Indicators!$J:$J,0.05))/(PERCENTILE(Indicators!$J:$J,0.95)-PERCENTILE(Indicators!$J:$J,0.05))*10)) -> 0 | N9: =MAX(0,MIN(10,(PERCENTILE(Indicators!$K$2:$K$121,0.95)-Table1[[#This Row],[Net FII (cr)]])/(PERCENTILE(Indicators!$K$2:$K$121,0.95)-PERCENTILE(Indicators!$K$2:$K$121,0.05))*10)) -> 3.0099905
A10: Net FII (cr) | B10: ⬇️ High Inflow = Low Risk | C10: INVERSE | E10: 42005 | F10: =MAX(0,MIN(10,(PERCENTILE(Indicators!$K$2:$K$121,0.95)-Table1[[#This Row],[Net FII (cr)]])/(PERCENTILE(Indicators!$K$2:$K$121,0.95)-PERCENTILE(Indicators!$K$2:$K$121,0.05))*10)) -> 4.5024807 | G10: =MAX(0,MIN(10,(Indicators!C11-PERCENTILE(Indicators!$C:$C,0.05))/(PERCENTILE(Indicators!$C:$C,0.95)-PERCENTILE(Indicators!$C:$C,0.05))*10)) -> 5.5291763 | H10: =MAX(0,MIN(10,(Indicators!D11-PERCENTILE(Indicators!$D:$D,0.05))/(PERCENTILE(Indicators!$D:$D,0.95)-PERCENTILE(Indicators!$D:$D,0.05))*10)) -> 10 | I10: =MAX(0,MIN(10,(Table1[[#This Row],[INDIA VIX]]-PERCENTILE(Indicators!$E$2:$E$121,0.05))/(PERCENTILE(Indicators!$E$2:$E$121,0.95)-PERCENTILE(Indicators!$E$2:$E$121,0.05))*10)) -> 2.0631745 | J10: =MAX(0,MIN(10,(Indicators!G11-PERCENTILE(Indicators!$G:$G,0.05))/(PERCENTILE(Indicators!$G:$G,0.95)-PERCENTILE(Indicators!$G:$G,0.05))*10)) -> 2.6735311 | K10: =MAX(0,MIN(10,(Indicators!H11-PERCENTILE(Indicators!$H:$H,0.05))/(PERCENTILE(Indicators!$H:$H,0.95)-PERCENTILE(Indicators!$H:$H,0.05))*10)) -> 1.7686505 | L10: =MAX(0,MIN(10,(Indicators!I11-PERCENTILE(Indicators!$I:$I,0.05))/(PERCENTILE(Indicators!$I:$I,0.95)-PERCENTILE(Indicators!$I:$I,0.05))*10)) -> 0.68734657 | M10: =MAX(0,MIN(10,(Indicators!J11-PERCENTILE(Indicators!$J:$J,0.05))/(PERCENTILE(Indicators!$J:$J,0.95)-PERCENTILE(Indicators!$J:$J,0.05))*10)) -> 2.9276387 | N10: =MAX(0,MIN(10,(PERCENTILE(Indicators!$K$2:$K$121,0.95)-Table1[[#This Row],[Net FII (cr)]])/(PERCENTILE(Indicators!$K$2:$K$121,0.95)-PERCENTILE(Indicators!$K$2:$K$121,0.05))*10)) -> 4.5024807
E11: 42036 | F11: =MAX(0,MIN(10,(PERCENTILE(Indicators!$K$2:$K$121,0.95)-Table1[[#This Row],[Net FII (cr)]])/(PERCENTILE(Indicators!$K$2:$K$121,0.95)-PERCENTILE(Indicators!$K$2:$K$121,0.05))*10)) -> 2.085714 | G11: =MAX(0,MIN(10,(Indicators!C12-PERCENTILE(Indicators!$C:$C,0.05))/(PERCENTILE(Indicators!$C:$C,0.95)-PERCENTILE(Indicators!$C:$C,0.05))*10)) -> 6.4183557 | H11: =MAX(0,MIN(10,(Indicators!D12-PERCENTILE(Indicators!$D:$D,0.05))/(PERCENTILE(Indicators!$D:$D,0.95)-PERCENTILE(Indicators!$D:$D,0.05))*10)) -> 9.375 | I11: =MAX(0,MIN(10,(Table1[[#This Row],[INDIA VIX]]-PERCENTILE(Indicators!$E$2:$E$121,0.05))/(PERCENTILE(Indicators!$E$2:$E$121,0.95)-PERCENTILE(Indicators!$E$2:$E$121,0.05))*10)) -> 5.1374765 | J11: =MAX(0,MIN(10,(Indicators!G12-PERCENTILE(Indicators!$G:$G,0.05))/(PERCENTILE(Indicators!$G:$G,0.95)-PERCENTILE(Indicators!$G:$G,0.05))*10)) -> 1.525898 | K11: =MAX(0,MIN(10,(Indicators!H12-PERCENTILE(Indicators!$H:$H,0.05))/(PERCENTILE(Indicators!$H:$H,0.95)-PERCENTILE(Indicators!$H:$H,0.05))*10)) -> 2.8583403 | L11: =MAX(0,MIN(10,(Indicators!I12-PERCENTILE(Indicators!$I:$I,0.05))/(PERCENTILE(Indicators!$I:$I,0.95)-PERCENTILE(Indicators!$I:$I,0.05))*10)) -> 3.0082571 | M11: =MAX(0,MIN(10,(Indicators!J12-PERCENTILE(Indicators!$J:$J,0.05))/(PERCENTILE(Indicators!$J:$J,0.95)-PERCENTILE(Indicators!$J:$J,0.05))*10)) -> 10 | N11: =MAX(0,MIN(10,(PERCENTILE(Indicators!$K$2:$K$121,0.95)-Table1[[#This Row],[Net FII (cr)]])/(PERCENTILE(Indicators!$K$2:$K$121,0.95)-PERCENTILE(Indicators!$K$2:$K$121,0.05))*10)) -> 2.085714
E12: 42064 | F12: =MAX(0,MIN(10,(PERCENTILE(Indicators!$K$2:$K$121,0.95)-Table1[[#This Row],[Net FII (cr)]])/(PERCENTILE(Indicators!$K$2:$K$121,0.95)-PERCENTILE(Indicators!$K$2:$K$121,0.05))*10)) -> 3.1130257 | G12: =MAX(0,MIN(10,(Indicators!C13-PERCENTILE(Indicators!$C:$C,0.05))/(PERCENTILE(Indicators!$C:$C,0.95)-PERCENTILE(Indicators!$C:$C,0.05))*10)) -> 6.184986 | H12: =MAX(0,MIN(10,(Indicators!D13-PERCENTILE(Indicators!$D:$D,0.05))/(PERCENTILE(Indicators!$D:$D,0.95)-PERCENTILE(Indicators!$D:$D,0.05))*10)) -> 9.375 | I12: =MAX(0,MIN(10,(Table1[[#This Row],[INDIA VIX]]-PERCENTILE(Indicators!$E$2:$E$121,0.05))/(PERCENTILE(Indicators!$E$2:$E$121,0.95)-PERCENTILE(Indicators!$E$2:$E$121,0.05))*10)) -> 3.1888467 | J12: =MAX(0,MIN(10,(Indicators!G13-PERCENTILE(Indicators!$G:$G,0.05))/(PERCENTILE(Indicators!$G:$G,0.95)-PERCENTILE(Indicators!$G:$G,0.05))*10)) -> 2.1623632 | K12: =MAX(0,MIN(10,(Indicators!H13-PERCENTILE(Indicators!$H:$H,0.05))/(PERCENTILE(Indicators!$H:$H,0.95)-PERCENTILE(Indicators!$H:$H,0.05))*10)) -> 1.9362951 | L12: =MAX(0,MIN(10,(Indicators!I13-PERCENTILE(Indicators!$I:$I,0.05))/(PERCENTILE(Indicators!$I:$I,0.95)-PERCENTILE(Indicators!$I:$I,0.05))*10)) -> 6.6012051 | M12: =MAX(0,MIN(10,(Indicators!J13-PERCENTILE(Indicators!$J:$J,0.05))/(PERCENTILE(Indicators!$J:$J,0.95)-PERCENTILE(Indicators!$J:$J,0.05))*10)) -> 1.7893366 | N12: =MAX(0,MIN(10,(PERCENTILE(Indicators!$K$2:$K$121,0.95)-Table1[[#This Row],[Net FII (cr)]])/(PERCENTILE(Indicators!$K$2:$K$121,0.95)-PERCENTILE(Indicators!$K$2:$K$121,0.05))*10)) -> 3.1130257
E13: 42095 | F13: =MAX(0,MIN(10,(PERCENTILE(Indicators!$K$2:$K$121,0.95)-Table1[[#This Row],[Net FII (cr)]])/(PERCENTILE(Indicators!$K$2:$K$121,0.95)-PERCENTILE(Indicators!$K$2:$K$121,0.05))*10)) -> 3.5453231 | G13: =MAX(0,MIN(10,(Indicators!C14-PERCENTILE(Indicators!$C:$C,0.05))/(PERCENTILE(Indicators!$C:$C,0.95)-PERCENTILE(Indicators!$C:$C,0.05))*10)) -> 4.584014 | H13: =MAX(0,MIN(10,(Indicators!D14-PERCENTILE(Indicators!$D:$D,0.05))/(PERCENTILE(Indicators!$D:$D,0.95)-PERCENTILE(Indicators!$D:$D,0.05))*10)) -> 8.75 | I13: =MAX(0,MIN(10,(Table1[[#This Row],[INDIA VIX]]-PERCENTILE(Indicators!$E$2:$E$121,0.05))/(PERCENTILE(Indicators!$E$2:$E$121,0.95)-PERCENTILE(Indicators!$E$2:$E$121,0.05))*10)) -> 1.6813587 | J13: =MAX(0,MIN(10,(Indicators!G14-PERCENTILE(Indicators!$G:$G,0.05))/(PERCENTILE(Indicators!$G:$G,0.95)-PERCENTILE(Indicators!$G:$G,0.05))*10)) -> 3.6255771 | K13: =MAX(0,MIN(10,(Indicators!H14-PERCENTILE(Indicators!$H:$H,0.05))/(PERCENTILE(Indicators!$H:$H,0.95)-PERCENTILE(Indicators!$H:$H,0.05))*10)) -> 1.4333613 | L13: =MAX(0,MIN(10,(Indicators!I14-PERCENTILE(Indicators!$I:$I,0.05))/(PERCENTILE(Indicators!$I:$I,0.95)-PERCENTILE(Indicators!$I:$I,0.05))*10)) -> 8.743584 | M13: =MAX(0,MIN(10,(Indicators!J14-PERCENTILE(Indicators!$J:$J,0.05))/(PERCENTILE(Indicators!$J:$J,0.95)-PERCENTILE(Indicators!$J:$J,0.05))*10)) -> 10 | N13: =MAX(0,MIN(10,(PERCENTILE(Indicators!$K$2:$K$121,0.95)-Table1[[#This Row],[Net FII (cr)]])/(PERCENTILE(Indicators!$K$2:$K$121,0.95)-PERCENTILE(Indicators!$K$2:$K$121,0.05))*10)) -> 3.5453231
E14: 42125 | F14: =MAX(0,MIN(10,(PERCENTILE(Indicators!$K$2:$K$121,0.95)-Table1[[#This Row],[Net FII (cr)]])/(PERCENTILE(Indicators!$K$2:$K$121,0.95)-PERCENTILE(Indicators!$K$2:$K$121,0.05))*10)) -> 4.1527241 | G14: =MAX(0,MIN(10,(Indicators!C15-PERCENTILE(Indicators!$C:$C,0.05))/(PERCENTILE(Indicators!$C:$C,0.95)-PERCENTILE(Indicators!$C:$C,0.05))*10)) -> 4.8684551 | H14: =MAX(0,MIN(10,(Indicators!D15-PERCENTILE(Indicators!$D:$D,0.05))/(PERCENTILE(Indicators!$D:$D,0.95)-PERCENTILE(Indicators!$D:$D,0.05))*10)) -> 8.75 | I14: =MAX(0,MIN(10,(Table1[[#This Row],[INDIA VIX]]-PERCENTILE(Indicators!$E$2:$E$121,0.05))/(PERCENTILE(Indicators!$E$2:$E$121,0.95)-PERCENTILE(Indicators!$E$2:$E$121,0.05))*10)) -> 3.3440069 | J14: =MAX(0,MIN(10,(Indicators!G15-PERCENTILE(Indicators!$G:$G,0.05))/(PERCENTILE(Indicators!$G:$G,0.95)-PERCENTILE(Indicators!$G:$G,0.05))*10)) -> 2.8760697 | K14: =MAX(0,MIN(10,(Indicators!H15-PERCENTILE(Indicators!$H:$H,0.05))/(PERCENTILE(Indicators!$H:$H,0.95)-PERCENTILE(Indicators!$H:$H,0.05))*10)) -> 2.2715842 | L14: =MAX(0,MIN(10,(Indicators!I15-PERCENTILE(Indicators!$I:$I,0.05))/(PERCENTILE(Indicators!$I:$I,0.95)-PERCENTILE(Indicators!$I:$I,0.05))*10)) -> 5.0613702 | M14: =MAX(0,MIN(10,(Indicators!J15-PERCENTILE(Indicators!$J:$J,0.05))/(PERCENTILE(Indicators!$J:$J,0.95)-PERCENTILE(Indicators!$J:$J,0.05))*10)) -> 4.5963215 | N14: =MAX(0,MIN(10,(PERCENTILE(Indicators!$K$2:$K$121,0.95)-Table1[[#This Row],[Net FII (cr)]])/(PERCENTILE(Indicators!$K$2:$K$121,0.95)-PERCENTILE(Indicators!$K$2:$K$121,0.05))*10)) -> 4.1527241
E15: 42156 | F15: =MAX(0,MIN(10,(PERCENTILE(Indicators!$K$2:$K$121,0.95)-Table1[[#This Row],[Net FII (cr)]])/(PERCENTILE(Indicators!$K$2:$K$121,0.95)-PERCENTILE(Indicators!$K$2:$K$121,0.05))*10)) -> 7.4862226 | G15: =MAX(0,MIN(10,(Indicators!C16-PERCENTILE(Indicators!$C:$C,0.05))/(PERCENTILE(Indicators!$C:$C,0.95)-PERCENTILE(Indicators!$C:$C,0.05))*10)) -> 5.6422203 | H15: =MAX(0,MIN(10,(Indicators!D16-PERCENTILE(Indicators!$D:$D,0.05))/(PERCENTILE(Indicators!$D:$D,0.95)-PERCENTILE(Indicators!$D:$D,0.05))*10)) -> 8.75 | I15: =MAX(0,MIN(10,(Table1[[#This Row],[INDIA VIX]]-PERCENTILE(Indicators!$E$2:$E$121,0.05))/(PERCENTILE(Indicators!$E$2:$E$121,0.95)-PERCENTILE(Indicators!$E$2:$E$121,0.05))*10)) -> 2.9986994 | J15: =MAX(0,MIN(10,(Indicators!G16-PERCENTILE(Indicators!$G:$G,0.05))/(PERCENTILE(Indicators!$G:$G,0.95)-PERCENTILE(Indicators!$G:$G,0.05))*10)) -> 2.6952274 | K15: =MAX(0,MIN(10,(Indicators!H16-PERCENTILE(Indicators!$H:$H,0.05))/(PERCENTILE(Indicators!$H:$H,0.95)-PERCENTILE(Indicators!$H:$H,0.05))*10)) -> 2.3554065 | L15: =MAX(0,MIN(10,(Indicators!I16-PERCENTILE(Indicators!$I:$I,0.05))/(PERCENTILE(Indicators!$I:$I,0.95)-PERCENTILE(Indicators!$I:$I,0.05))*10)) -> 3.8116492 | M15: =MAX(0,MIN(10,(Indicators!J16-PERCENTILE(Indicators!$J:$J,0.05))/(PERCENTILE(Indicators!$J:$J,0.95)-PERCENTILE(Indicators!$J:$J,0.05))*10)) -> 4.2613443 | N15: =MAX(0,MIN(10,(PERCENTILE(Indicators!$K$2:$K$121,0.95)-Table1[[#This Row],[Net FII (cr)]])/(PERCENTILE(Indicators!$K$2:$K$121,0.95)-PERCENTILE(Indicators!$K$2:$K$121,0.05))*10)) -> 7.4862226
E16: 42186 | F16: =MAX(0,MIN(10,(PERCENTILE(Indicators!$K$2:$K$121,0.95)-Table1[[#This Row],[Net FII (cr)]])/(PERCENTILE(Indicators!$K$2:$K$121,0.95)-PERCENTILE(Indicators!$K$2:$K$121,0.05))*10)) -> 6.0600577 | G16: =MAX(0,MIN(10,(Indicators!C17-PERCENTILE(Indicators!$C:$C,0.05))/(PERCENTILE(Indicators!$C:$C,0.95)-PERCENTILE(Indicators!$C:$C,0.05))*10)) -> 2.253601 | H16: =MAX(0,MIN(10,(Indicators!D17-PERCENTILE(Indicators!$D:$D,0.05))/(PERCENTILE(Indicators!$D:$D,0.95)-PERCENTILE(Indicators!$D:$D,0.05))*10)) -> 8.125 | I16: =MAX(0,MIN(10,(Table1[[#This Row],[INDIA VIX]]-PERCENTILE(Indicators!$E$2:$E$121,0.05))/(PERCENTILE(Indicators!$E$2:$E$121,0.95)-PERCENTILE(Indicators!$E$2:$E$121,0.05))*10)) -> 3.1629867 | J16: =MAX(0,MIN(10,(Indicators!G17-PERCENTILE(Indicators!$G:$G,0.05))/(PERCENTILE(Indicators!$G:$G,0.95)-PERCENTILE(Indicators!$G:$G,0.05))*10)) -> 1.245424 | K16: =MAX(0,MIN(10,(Indicators!H17-PERCENTILE(Indicators!$H:$H,0.05))/(PERCENTILE(Indicators!$H:$H,0.95)-PERCENTILE(Indicators!$H:$H,0.05))*10)) -> 2.6068734 | L16: =MAX(0,MIN(10,(Indicators!I17-PERCENTILE(Indicators!$I:$I,0.05))/(PERCENTILE(Indicators!$I:$I,0.95)-PERCENTILE(Indicators!$I:$I,0.05))*10)) -> 5.6415979 | M16: =MAX(0,MIN(10,(Indicators!J17-PERCENTILE(Indicators!$J:$J,0.05))/(PERCENTILE(Indicators!$J:$J,0.95)-PERCENTILE(Indicators!$J:$J,0.05))*10)) -> 0 | N16: =MAX(0,MIN(10,(PERCENTILE(Indicators!$K$2:$K$121,0.95)-Table1[[#This Row],[Net FII (cr)]])/(PERCENTILE(Indicators!$K$2:$K$121,0.95)-PERCENTILE(Indicators!$K$2:$K$121,0.05))*10)) -> 6.0600577
E17: 42217 | F17: =MAX(0,MIN(10,(PERCENTILE(Indicators!$K$2:$K$121,0.95)-Table1[[#This Row],[Net FII (cr)]])/(PERCENTILE(Indicators!$K$2:$K$121,0.95)-PERCENTILE(Indicators!$K$2:$K$121,0.05))*10)) -> 5.2796927 | G17: =MAX(0,MIN(10,(Indicators!C18-PERCENTILE(Indicators!$C:$C,0.05))/(PERCENTILE(Indicators!$C:$C,0.95)-PERCENTILE(Indicators!$C:$C,0.05))*10)) -> 2.3516028 | H17: =MAX(0,MIN(10,(Indicators!D18-PERCENTILE(Indicators!$D:$D,0.05))/(PERCENTILE(Indicators!$D:$D,0.95)-PERCENTILE(Indicators!$D:$D,0.05))*10)) -> 8.125 | I17: =MAX(0,MIN(10,(Table1[[#This Row],[INDIA VIX]]-PERCENTILE(Indicators!$E$2:$E$121,0.05))/(PERCENTILE(Indicators!$E$2:$E$121,0.95)-PERCENTILE(Indicators!$E$2:$E$121,0.05))*10)) -> 1.7285153 | J17: =MAX(0,MIN(10,(Indicators!G18-PERCENTILE(Indicators!$G:$G,0.05))/(PERCENTILE(Indicators!$G:$G,0.95)-PERCENTILE(Indicators!$G:$G,0.05))*10)) -> 3.800807 | K17: =MAX(0,MIN(10,(Indicators!H18-PERCENTILE(Indicators!$H:$H,0.05))/(PERCENTILE(Indicators!$H:$H,0.95)-PERCENTILE(Indicators!$H:$H,0.05))*10)) -> 1.4333613 | L17: =MAX(0,MIN(10,(Indicators!I18-PERCENTILE(Indicators!$I:$I,0.05))/(PERCENTILE(Indicators!$I:$I,0.95)-PERCENTILE(Indicators!$I:$I,0.05))*10)) -> 10 | M17: =MAX(0,MIN(10,(Indicators!J18-PERCENTILE(Indicators!$J:$J,0.05))/(PERCENTILE(Indicators!$J:$J,0.95)-PERCENTILE(Indicators!$J:$J,0.05))*10)) -> 6.4542043 | N17: =MAX(0,MIN(10,(PERCENTILE(Indicators!$K$2:$K$121,0.95)-Table1[[#This Row],[Net FII (cr)]])/(PERCENTILE(Indicators!$K$2:$K$121,0.95)-PERCENTILE(Indicators!$K$2:$K$121,0.05))*10)) -> 5.2796927
E18: 42248 | F18: =MAX(0,MIN(10,(PERCENTILE(Indicators!$K$2:$K$121,0.95)-Table1[[#This Row],[Net FII (cr)]])/(PERCENTILE(Indicators!$K$2:$K$121,0.95)-PERCENTILE(Indicators!$K$2:$K$121,0.05))*10)) -> 7.8524198 | G18: =MAX(0,MIN(10,(Indicators!C19-PERCENTILE(Indicators!$C:$C,0.05))/(PERCENTILE(Indicators!$C:$C,0.95)-PERCENTILE(Indicators!$C:$C,0.05))*10)) -> 3.6861451 | H18: =MAX(0,MIN(10,(Indicators!D19-PERCENTILE(Indicators!$D:$D,0.05))/(PERCENTILE(Indicators!$D:$D,0.95)-PERCENTILE(Indicators!$D:$D,0.05))*10)) -> 8.125 | I18: =MAX(0,MIN(10,(Table1[[#This Row],[INDIA VIX]]-PERCENTILE(Indicators!$E$2:$E$121,0.05))/(PERCENTILE(Indicators!$E$2:$E$121,0.95)-PERCENTILE(Indicators!$E$2:$E$121,0.05))*10)) -> 7.8284415 | J18: =MAX(0,MIN(10,(Indicators!G19-PERCENTILE(Indicators!$G:$G,0.05))/(PERCENTILE(Indicators!$G:$G,0.95)-PERCENTILE(Indicators!$G:$G,0.05))*10)) -> 3.2920273 | K18: =MAX(0,MIN(10,(Indicators!H19-PERCENTILE(Indicators!$H:$H,0.05))/(PERCENTILE(Indicators!$H:$H,0.95)-PERCENTILE(Indicators!$H:$H,0.05))*10)) -> 1.5171836 | L18: =MAX(0,MIN(10,(Indicators!I19-PERCENTILE(Indicators!$I:$I,0.05))/(PERCENTILE(Indicators!$I:$I,0.95)-PERCENTILE(Indicators!$I:$I,0.05))*10)) -> 1.2898906 | M18: =MAX(0,MIN(10,(Indicators!J19-PERCENTILE(Indicators!$J:$J,0.05))/(PERCENTILE(Indicators!$J:$J,0.95)-PERCENTILE(Indicators!$J:$J,0.05))*10)) -> 1.8482677 | N18: =MAX(0,MIN(10,(PERCENTILE(Indicators!$K$2:$K$121,0.95)-Table1[[#This Row],[Net FII (cr)]])/(PERCENTILE(Indicators!$K$2:$K$121,0.95)-PERCENTILE(Indicators!$K$2:$K$121,0.05))*10)) -> 7.8524198
E19: 42278 | F19: =MAX(0,MIN(10,(PERCENTILE(Indicators!$K$2:$K$121,0.95)-Table1[[#This Row],[Net FII (cr)]])/(PERCENTILE(Indicators!$K$2:$K$121,0.95)-PERCENTILE(Indicators!$K$2:$K$121,0.05))*10)) -> 6.530754 | G19: =MAX(0,MIN(10,(Indicators!C20-PERCENTILE(Indicators!$C:$C,0.05))/(PERCENTILE(Indicators!$C:$C,0.95)-PERCENTILE(Indicators!$C:$C,0.05))*10)) -> 4.8430506 | H19: =MAX(0,MIN(10,(Indicators!D20-PERCENTILE(Indicators!$D:$D,0.05))/(PERCENTILE(Indicators!$D:$D,0.95)-PERCENTILE(Indicators!$D:$D,0.05))*10)) -> 6.875 | I19: =MAX(0,MIN(10,(Table1[[#This Row],[INDIA VIX]]-PERCENTILE(Indicators!$E$2:$E$121,0.05))/(PERCENTILE(Indicators!$E$2:$E$121,0.95)-PERCENTILE(Indicators!$E$2:$E$121,0.05))*10)) -> 4.8043384 | J19: =MAX(0,MIN(10,(Indicators!G20-PERCENTILE(Indicators!$G:$G,0.05))/(PERCENTILE(Indicators!$G:$G,0.95)-PERCENTILE(Indicators!$G:$G,0.05))*10)) -> 3.430526 | K19: =MAX(0,MIN(10,(Indicators!H20-PERCENTILE(Indicators!$H:$H,0.05))/(PERCENTILE(Indicators!$H:$H,0.95)-PERCENTILE(Indicators!$H:$H,0.05))*10)) -> 1.4333613 | L19: =MAX(0,MIN(10,(Indicators!I20-PERCENTILE(Indicators!$I:$I,0.05))/(PERCENTILE(Indicators!$I:$I,0.95)-PERCENTILE(Indicators!$I:$I,0.05))*10)) -> 3.9901808 | M19: =MAX(0,MIN(10,(Indicators!J20-PERCENTILE(Indicators!$J:$J,0.05))/(PERCENTILE(Indicators!$J:$J,0.95)-PERCENTILE(Indicators!$J:$J,0.05))*10)) -> 5.9951614 | N19: =MAX(0,MIN(10,(PERCENTILE(Indicators!$K$2:$K$121,0.95)-Table1[[#This Row],[Net FII (cr)]])/(PERCENTILE(Indicators!$K$2:$K$121,0.95)-PERCENTILE(Indicators!$K$2:$K$121,0.05))*10)) -> 6.530754
E20: 42309 | F20: =MAX(0,MIN(10,(PERCENTILE(Indicators!$K$2:$K$121,0.95)-Table1[[#This Row],[Net FII (cr)]])/(PERCENTILE(Indicators!$K$2:$K$121,0.95)-PERCENTILE(Indicators!$K$2:$K$121,0.05))*10)) -> 3.3621119 | G20: =MAX(0,MIN(10,(Indicators!C21-PERCENTILE(Indicators!$C:$C,0.05))/(PERCENTILE(Indicators!$C:$C,0.95)-PERCENTILE(Indicators!$C:$C,0.05))*10)) -> 5.6694117 | H20: =MAX(0,MIN(10,(Indicators!D21-PERCENTILE(Indicators!$D:$D,0.05))/(PERCENTILE(Indicators!$D:$D,0.95)-PERCENTILE(Indicators!$D:$D,0.05))*10)) -> 6.875 | I20: =MAX(0,MIN(10,(Table1[[#This Row],[INDIA VIX]]-PERCENTILE(Indicators!$E$2:$E$121,0.05))/(PERCENTILE(Indicators!$E$2:$E$121,0.95)-PERCENTILE(Indicators!$E$2:$E$121,0.05))*10)) -> 3.7425557 | J20: =MAX(0,MIN(10,(Indicators!G21-PERCENTILE(Indicators!$G:$G,0.05))/(PERCENTILE(Indicators!$G:$G,0.95)-PERCENTILE(Indicators!$G:$G,0.05))*10)) -> 2.7294193 | K20: =MAX(0,MIN(10,(Indicators!H21-PERCENTILE(Indicators!$H:$H,0.05))/(PERCENTILE(Indicators!$H:$H,0.95)-PERCENTILE(Indicators!$H:$H,0.05))*10)) -> 0.93042749 | L20: =MAX(0,MIN(10,(Indicators!I21-PERCENTILE(Indicators!$I:$I,0.05))/(PERCENTILE(Indicators!$I:$I,0.95)-PERCENTILE(Indicators!$I:$I,0.05))*10)) -> 7.8509261 | M20: =MAX(0,MIN(10,(Indicators!J21-PERCENTILE(Indicators!$J:$J,0.05))/(PERCENTILE(Indicators!$J:$J,0.95)-PERCENTILE(Indicators!$J:$J,0.05))*10)) -> 2.0715859 | N20: =MAX(0,MIN(10,(PERCENTILE(Indicators!$K$2:$K$121,0.95)-Table1[[#This Row],[Net FII (cr)]])/(PERCENTILE(Indicators!$K$2:$K$121,0.95)-PERCENTILE(Indicators!$K$2:$K$121,0.05))*10)) -> 3.3621119
E21: 42339 | F21: =MAX(0,MIN(10,(PERCENTILE(Indicators!$K$2:$K$121,0.95)-Table1[[#This Row],[Net FII (cr)]])/(PERCENTILE(Indicators!$K$2:$K$121,0.95)-PERCENTILE(Indicators!$K$2:$K$121,0.05))*10)) -> 7.0984048 | G21: =MAX(0,MIN(10,(Indicators!C22-PERCENTILE(Indicators!$C:$C,0.05))/(PERCENTILE(Indicators!$C:$C,0.95)-PERCENTILE(Indicators!$C:$C,0.05))*10)) -> 6.0648746 | H21: =MAX(0,MIN(10,(Indicators!D22-PERCENTILE(Indicators!$D:$D,0.05))/(PERCENTILE(Indicators!$D:$D,0.95)-PERCENTILE(Indicators!$D:$D,0.05))*10)) -> 6.875 | I21: =MAX(0,MIN(10,(Table1[[#This Row],[INDIA VIX]]-PERCENTILE(Indicators!$E$2:$E$121,0.05))/(PERCENTILE(Indicators!$E$2:$E$121,0.95)-PERCENTILE(Indicators!$E$2:$E$121,0.05))*10)) -> 2.8602721 | J21: =MAX(0,MIN(10,(Indicators!G22-PERCENTILE(Indicators!$G:$G,0.05))/(PERCENTILE(Indicators!$G:$G,0.95)-PERCENTILE(Indicators!$G:$G,0.05))*10)) -> 2.5434583 | K21: =MAX(0,MIN(10,(Indicators!H22-PERCENTILE(Indicators!$H:$H,0.05))/(PERCENTILE(Indicators!$H:$H,0.95)-PERCENTILE(Indicators!$H:$H,0.05))*10)) -> 0.93042749 | L21: =MAX(0,MIN(10,(Indicators!I22-PERCENTILE(Indicators!$I:$I,0.05))/(PERCENTILE(Indicators!$I:$I,0.95)-PERCENTILE(Indicators!$I:$I,0.05))*10)) -> 3.454586 | M21: =MAX(0,MIN(10,(Indicators!J22-PERCENTILE(Indicators!$J:$J,0.05))/(PERCENTILE(Indicators!$J:$J,0.95)-PERCENTILE(Indicators!$J:$J,0.05))*10)) -> 0.0089947582 | N21: =MAX(0,MIN(10,(PERCENTILE(Indicators!$K$2:$K$121,0.95)-Table1[[#This Row],[Net FII (cr)]])/(PERCENTILE(Indicators!$K$2:$K$121,0.95)-PERCENTILE(Indicators!$K$2:$K$121,0.05))*10)) -> 7.0984048
E22: 42370 | F22: =MAX(0,MIN(10,(PERCENTILE(Indicators!$K$2:$K$121,0.95)-Table1[[#This Row],[Net FII (cr)]])/(PERCENTILE(Indicators!$K$2:$K$121,0.95)-PERCENTILE(Indicators!$K$2:$K$121,0.05))*10)) -> 6.8145231 | G22: =MAX(0,MIN(10,(Indicators!C23-PERCENTILE(Indicators!$C:$C,0.05))/(PERCENTILE(Indicators!$C:$C,0.95)-PERCENTILE(Indicators!$C:$C,0.05))*10)) -> 6.221656 | H22: =MAX(0,MIN(10,(Indicators!D23-PERCENTILE(Indicators!$D:$D,0.05))/(PERCENTILE(Indicators!$D:$D,0.95)-PERCENTILE(Indicators!$D:$D,0.05))*10)) -> 6.875 | I22: =MAX(0,MIN(10,(Table1[[#This Row],[INDIA VIX]]-PERCENTILE(Indicators!$E$2:$E$121,0.05))/(PERCENTILE(Indicators!$E$2:$E$121,0.95)-PERCENTILE(Indicators!$E$2:$E$121,0.05))*10)) -> 1.3025852 | J22: =MAX(0,MIN(10,(Indicators!G23-PERCENTILE(Indicators!$G:$G,0.05))/(PERCENTILE(Indicators!$G:$G,0.95)-PERCENTILE(Indicators!$G:$G,0.05))*10)) -> 5.020258 | K22: =MAX(0,MIN(10,(Indicators!H23-PERCENTILE(Indicators!$H:$H,0.05))/(PERCENTILE(Indicators!$H:$H,0.95)-PERCENTILE(Indicators!$H:$H,0.05))*10)) -> 0 | L22: =MAX(0,MIN(10,(Indicators!I23-PERCENTILE(Indicators!$I:$I,0.05))/(PERCENTILE(Indicators!$I:$I,0.95)-PERCENTILE(Indicators!$I:$I,0.05))*10)) -> 9.9263557 | M22: =MAX(0,MIN(10,(Indicators!J23-PERCENTILE(Indicators!$J:$J,0.05))/(PERCENTILE(Indicators!$J:$J,0.95)-PERCENTILE(Indicators!$J:$J,0.05))*10)) -> 3.814708 | N22: =MAX(0,MIN(10,(PERCENTILE(Indicators!$K$2:$K$121,0.95)-Table1[[#This Row],[Net FII (cr)]])/(PERCENTILE(Indicators!$K$2:$K$121,0.95)-PERCENTILE(Indicators!$K$2:$K$121,0.05))*10)) -> 6.8145231
... E120: 45352 | F120: =MAX(0,MIN(10,(PERCENTILE(Indicators!$K$2:$K$121,0.95)-Table1[[#This Row],[Net FII (cr)]])/(PERCENTILE(Indicators!$K$2:$K$121,0.95)-PERCENTILE(Indicators!$K$2:$K$121,0.05))*10)) -> 2.2962887 | G120: =MAX(0,MIN(10,(Indicators!C121-PERCENTILE(Indicators!$C:$C,0.05))/(PERCENTILE(Indicators!$C:$C,0.95)-PERCENTILE(Indicators!$C:$C,0.05))*10)) -> 4.5600732 | H120: =MAX(0,MIN(10,(Indicators!D121-PERCENTILE(Indicators!$D:$D,0.05))/(PERCENTILE(Indicators!$D:$D,0.95)-PERCENTILE(Indicators!$D:$D,0.05))*10)) -> 6.25 | I120: =MAX(0,MIN(10,(Table1[[#This Row],[INDIA VIX]]-PERCENTILE(Indicators!$E$2:$E$121,0.05))/(PERCENTILE(Indicators!$E$2:$E$121,0.95)-PERCENTILE(Indicators!$E$2:$E$121,0.05))*10)) -> 2.3385079 | J120: =MAX(0,MIN(10,(Indicators!G121-PERCENTILE(Indicators!$G:$G,0.05))/(PERCENTILE(Indicators!$G:$G,0.95)-PERCENTILE(Indicators!$G:$G,0.05))*10)) -> 1.4959292 | K120: =MAX(0,MIN(10,(Indicators!H121-PERCENTILE(Indicators!$H:$H,0.05))/(PERCENTILE(Indicators!$H:$H,0.95)-PERCENTILE(Indicators!$H:$H,0.05))*10)) -> 2.1039396 | L120: =MAX(0,MIN(10,(Indicators!I121-PERCENTILE(Indicators!$I:$I,0.05))/(PERCENTILE(Indicators!$I:$I,0.95)-PERCENTILE(Indicators!$I:$I,0.05))*10)) -> 5.5076992 | M120: =MAX(0,MIN(10,(Indicators!J121-PERCENTILE(Indicators!$J:$J,0.05))/(PERCENTILE(Indicators!$J:$J,0.95)-PERCENTILE(Indicators!$J:$J,0.05))*10)) -> 7.1241587 | N120: =MAX(0,MIN(10,(PERCENTILE(Indicators!$K$2:$K$121,0.95)-Table1[[#This Row],[Net FII (cr)]])/(PERCENTILE(Indicators!$K$2:$K$121,0.95)-PERCENTILE(Indicators!$K$2:$K$121,0.05))*10)) -> 2.2962887

Sheet Risk Score
A1: DATE | B1: MACRO SCORE | C1: MARKET SCORE | D1: EXTERNAL SCORE | E1: COMPOSITE SCORE | F1: SIGNAL
A2: 41760 | B2: =AVERAGE(Table4[[#This Row],[GDP]],Table4[[#This Row],[CPI]],Table4[[#This Row],[REPO RATE]]) -> 8.6106763 | C2: =AVERAGE(Table4[[#This Row],[INDIA VIX]],Table4[[#This Row],[GOLD/NIFTY]],Table4[[#This Row],[NIFTY PE RATIO]]) -> 5.1787778 | D2: =AVERAGE(Table4[[#This Row],[USD/INR % CHANGE]],Table4[[#This Row],[OIL % CHANGE]],Table4[[#This Row],[Net FII (cr)]]) -> 3.7405379 | E2: =(B2*0.25)+(C2*0.45)+(D2*0.3) -> 5.6052805 | F2: =IF(E2<=5,"Green",IF(E2<=6.5,"Amber","Red")) -> Amber
A3: 41791 | B3: =AVERAGE(Table4[[#This Row],[GDP]],Table4[[#This Row],[CPI]],Table4[[#This Row],[REPO RATE]]) -> 7.255349 | C3: =AVERAGE(Table4[[#This Row],[INDIA VIX]],Table4[[#This Row],[GOLD/NIFTY]],Table4[[#This Row],[NIFTY PE RATIO]]) -> 2.9314141 | D3: =AVERAGE(Table4[[#This Row],[USD/INR % CHANGE]],Table4[[#This Row],[OIL % CHANGE]],Table4[[#This Row],[Net FII (cr)]]) -> 5.2673436 | E3: =(B3*0.25)+(C3*0.45)+(D3*0.3) -> 4.7131767 | F3: =IF(E3<=5,"Green",IF(E3<=6.5,"Amber","Red")) -> Green
A4: 41821 | B4: =AVERAGE(Table4[[#This Row],[GDP]],Table4[[#This Row],[CPI]],Table4[[#This Row],[REPO RATE]]) -> 7.4738358 | C4: =AVERAGE(Table4[[#This Row],[INDIA VIX]],Table4[[#This Row],[GOLD/NIFTY]],Table4[[#This Row],[NIFTY PE RATIO]]) -> 3.0740827 | D4: =AVERAGE(Table4[[#This Row],[USD/INR % CHANGE]],Table4[[#This Row],[OIL % CHANGE]],Table4[[#This Row],[Net FII (cr)]]) -> 4.0881764 | E4: =(B4*0.25)+(C4*0.45)+(D4*0.3) -> 4.4782491 | F4: =IF(E4<=5,"Green",IF(E4<=6.5,"Amber","Red")) -> Green
A5: 41852 | B5: =AVERAGE(Table4[[#This Row],[GDP]],Table4[[#This Row],[CPI]],Table4[[#This Row],[REPO RATE]]) -> 7.2733957 | C5: =AVERAGE(Table4[[#This Row],[INDIA VIX]],Table4[[#This Row],[GOLD/NIFTY]],Table4[[#This Row],[NIFTY PE RATIO]]) -> 2.0471907 | D5: =AVERAGE(Table4[[#This Row],[USD/INR % CHANGE]],Table4[[#This Row],[OIL % CHANGE]],Table4[[#This Row],[Net FII (cr)]]) -> 3.453766 | E5: =(B5*0.25)+(C5*0.45)+(D5*0.3) -> 3.7757145 | F5: =IF(E5<=5,"Green",IF(E5<=6.5,"Amber","Red")) -> Green
A6: 41883 | B6: =AVERAGE(Table4[[#This Row],[GDP]],Table4[[#This Row],[CPI]],Table4[[#This Row],[REPO RATE]]) -> 6.6528629 | C6: =AVERAGE(Table4[[#This Row],[INDIA VIX]],Table4[[#This Row],[GOLD/NIFTY]],Table4[[#This Row],[NIFTY PE RATIO]]) -> 1.6345849 | D6: =AVERAGE(Table4[[#This Row],[USD/INR % CHANGE]],Table4[[#This Row],[OIL % CHANGE]],Table4[[#This Row],[Net FII (cr)]]) -> 5.2022759 | E6: =(B6*0.25)+(C6*0.45)+(D6*0.3) -> 3.9594617 | F6: =IF(E6<=5,"Green",IF(E6<=6.5,"Amber","Red")) -> Green
A7: 41913 | B7: =AVERAGE(Table4[[#This Row],[GDP]],Table4[[#This Row],[CPI]],Table4[[#This Row],[REPO RATE]]) -> 5.9653703 | C7: =AVERAGE(Table4[[#This Row],[INDIA VIX]],Table4[[#This Row],[GOLD/NIFTY]],Table4[[#This Row],[NIFTY PE RATIO]]) -> 1.349452 | D7: =AVERAGE(Table4[[#This Row],[USD/INR % CHANGE]],Table4[[#This Row],[OIL % CHANGE]],Table4[[#This Row],[Net FII (cr)]]) -> 2.7256958 | E7: =(B7*0.25)+(C7*0.45)+(D7*0.3) -> 2.9163047 | F7: =IF(E7<=5,"Green",IF(E7<=6.5,"Amber","Red")) -> Green
A8: 41944 | B8: =AVERAGE(Table4[[#This Row],[GDP]],Table4[[#This Row],[CPI]],Table4[[#This Row],[REPO RATE]]) -> 5.0592419 | C8: =AVERAGE(Table4[[#This Row],[INDIA VIX]],Table4[[#This Row],[GOLD/NIFTY]],Table4[[#This Row],[NIFTY PE RATIO]]) -> 1.4103021 | D8: =AVERAGE(Table4[[#This Row],[USD/INR % CHANGE]],Table4[[#This Row],[OIL % CHANGE]],Table4[[#This Row],[Net FII (cr)]]) -> 3.7404551 | E8: =(B8*0.25)+(C8*0.45)+(D8*0.3) -> 3.021583 | F8: =IF(E8<=5,"Green",IF(E8<=6.5,"Amber","Red")) -> Green
A9: 41974 | B9: =AVERAGE(Table4[[#This Row],[GDP]],Table4[[#This Row],[CPI]],Table4[[#This Row],[REPO RATE]]) -> 5.3952411 | C9: =AVERAGE(Table4[[#This Row],[INDIA VIX]],Table4[[#This Row],[GOLD/NIFTY]],Table4[[#This Row],[NIFTY PE RATIO]]) -> 1.51584 | D9: =AVERAGE(Table4[[#This Row],[USD/INR % CHANGE]],Table4[[#This Row],[OIL % CHANGE]],Table4[[#This Row],[Net FII (cr)]]) -> 3.4343351 | E9: =(B9*0.25)+(C9*0.45)+(D9*0.3) -> 3.0612388 | F9: =IF(E9<=5,"Green",IF(E9<=6.5,"Amber","Red")) -> Green
A10: 42005 | B10: =AVERAGE(Table4[[#This Row],[GDP]],Table4[[#This Row],[CPI]],Table4[[#This Row],[REPO RATE]]) -> 6.677219 | C10: =AVERAGE(Table4[[#This Row],[INDIA VIX]],Table4[[#This Row],[GOLD/NIFTY]],Table4[[#This Row],[NIFTY PE RATIO]]) -> 2.168452 | D10: =AVERAGE(Table4[[#This Row],[USD/INR % CHANGE]],Table4[[#This Row],[OIL % CHANGE]],Table4[[#This Row],[Net FII (cr)]]) -> 2.705822 | E10: =(B10*0.25)+(C10*0.45)+(D10*0.3) -> 3.4568548 | F10: =IF(E10<=5,"Green",IF(E10<=6.5,"Amber","Red")) -> Green
A11: 42036 | B11: =AVERAGE(Table4[[#This Row],[GDP]],Table4[[#This Row],[CPI]],Table4[[#This Row],[REPO RATE]]) -> 5.9596899 | C11: =AVERAGE(Table4[[#This Row],[INDIA VIX]],Table4[[#This Row],[GOLD/NIFTY]],Table4[[#This Row],[NIFTY PE RATIO]]) -> 3.1739049 | D11: =AVERAGE(Table4[[#This Row],[USD/INR % CHANGE]],Table4[[#This Row],[OIL % CHANGE]],Table4[[#This Row],[Net FII (cr)]]) -> 5.0313237 | E11: =(B11*0.25)+(C11*0.45)+(D11*0.3) -> 4.4275768 | F11: =IF(E11<=5,"Green",IF(E11<=6.5,"Amber","Red")) -> Green
A12: 42064 | B12: =AVERAGE(Table4[[#This Row],[GDP]],Table4[[#This Row],[CPI]],Table4[[#This Row],[REPO RATE]]) -> 6.2243372 | C12: =AVERAGE(Table4[[#This Row],[INDIA VIX]],Table4[[#This Row],[GOLD/NIFTY]],Table4[[#This Row],[NIFTY PE RATIO]]) -> 2.4291683 | D12: =AVERAGE(Table4[[#This Row],[USD/INR % CHANGE]],Table4[[#This Row],[OIL % CHANGE]],Table4[[#This Row],[Net FII (cr)]]) -> 3.8345224 | E12: =(B12*0.25)+(C12*0.45)+(D12*0.3) -> 3.7995668 | F12: =IF(E12<=5,"Green",IF(E12<=6.5,"Amber","Red")) -> Green
A13: 42095 | B13: =AVERAGE(Table4[[#This Row],[GDP]],Table4[[#This Row],[CPI]],Table4[[#This Row],[REPO RATE]]) -> 5.6264457 | C13: =AVERAGE(Table4[[#This Row],[INDIA VIX]],Table4[[#This Row],[GOLD/NIFTY]],Table4[[#This Row],[NIFTY PE RATIO]]) -> 2.2467657 | D13: =AVERAGE(Table4[[#This Row],[USD/INR % CHANGE]],Table4[[#This Row],[OIL % CHANGE]],Table4[[#This Row],[Net FII (cr)]]) -> 7.4296357 | E13: =(B13*0.25)+(C13*0.45)+(D13*0.3) -> 4.6465467 | F13: =IF(E13<=5,"Green",IF(E13<=6.5,"Amber","Red")) -> Green
... A120: 45352 | B120: =AVERAGE(Table4[[#This Row],[GDP]],Table4[[#This Row],[CPI]],Table4[[#This Row],[REPO RATE]]) -> 4.3687873 | C120: =AVERAGE(Table4[[#This Row],[INDIA VIX]],Table4[[#This Row],[GOLD/NIFTY]],Table4[[#This Row],[NIFTY PE RATIO]]) -> 1.9794589 | D120: =AVERAGE(Table4[[#This Row],[USD/INR % CHANGE]],Table4[[#This Row],[OIL % CHANGE]],Table4[[#This Row],[Net FII (cr)]]) -> 4.9760489 | E120: =(B120*0.25)+(C120*0.45)+(D120*0.3) -> 3.475768 | F120: =IF(E120<=5,"Green",IF(E120<=6.5,"Amber","Red")) -> Green

Sheet Stress Returns
A1: STRESS PERIOD | B1: DATES | C1: NIFTY 50 | D1: NIFTY BANK | E1: NIFTY IT | F1: GOLD | G1: 10Y g-sec YIELD | H1: USD/INR
A2: 2016 DEMONETISATION | B2: 42675 | C2: -0.0465 | D2: -0.0459 | E2: 0.0005 | F2: -0.0498 | G2: -0.0932 | H2: 0.0287 | J2: Cumulative Return Per Stress Period
B3: 42705 | C3: -0.0047 | D3: -0.0242 | E3: 0.0309 | F3: -0.0306 | G3: 0.0431 | H3: -0.0094 | J3: Stress Period | K3: Nifty 50 | L3: NIFTY Bank | M3: Nifty IT | N3: Gold | O3: Bonds | P3: USD/INR
B4: 42736 | C4: 0.0459 | D4: 0.0736 | E4: -0.053 | F4: 0.0258 | G4: -0.0161 | H4: -0.0067 | J4: 2016 Demonetisation | K4: =SUM(C2:C6) -> 0.065 | L4: =SUM(D2:D6) -> 0.1001 | M4: =SUM(E2:E6) -> 0.065 | N4: =SUM(F2:F6) -> -0.0604 | O4: =SUM(G2:G6) -> -0.0248 | P4: =SUM(H2:H6) -> -0.0268
B5: 42767 | C5: 0.0372 | D5: 0.056 | E5: 0.0845 | F5: 0.0272 | G5: 0.0723 | H5: -0.0117 | J5: 2018 IL&FS | K5: =SUM(C7:C13) -> 0.0024 | L5: =SUM(D7:D13) -> 0.0979 | M5: =SUM(E7:E13) -> -0.007 | N5: =SUM(F7:F13) -> 0.043 | O5: =SUM(G7:G13) -> -0.0772 | P5: =SUM(H7:H13) -> -0.0233
B6: 42795 | C6: 0.0331 | D6: 0.0406 | E6: 0.0021 | F6: -0.033 | G6: -0.0309 | H6: -0.0277 | J6: 2020 COVID | K6: =SUM(C14:C20) -> 0.0009 | L6: =SUM(D14:D20) -> -0.1592 | M6: =SUM(E14:E20) -> 0.1499 | N6: =SUM(F14:F20) -> 0.2489 | O6: =SUM(G14:G20) -> -0.0799 | P6: =SUM(H14:H20) -> 0.0247
A7: 2018 IL & FC | B7: 43344 | C7: -0.0642 | D7: -0.1048 | E7: 0.0017 | F7: -0.0007 | G7: 0.0092 | H7: 0.0211 | J7: 2022 Rate Hikes | K7: =SUM(C21:C32) -> 0.0408 | L7: =SUM(D21:D32) -> 0.122 | M7: =SUM(E21:E32) -> -0.1075 | N7: =SUM(F21:F32) -> 0.0874 | O7: =SUM(G21:G32) -> 0.0997 | P7: =SUM(H21:H32) -> 0.0918
B8: 43374 | C8: -0.0498 | D8: 0.0013 | E8: -0.0567 | F8: 0.0497 | G8: -0.0213 | H8: 0.02
B9: 43405 | C9: 0.0472 | D9: 0.068 | E9: -0.0202 | F9: -0.0488 | G9: -0.0313 | H9: -0.0583
B10: 43435 | C10: -0.0013 | D10: 0.0111 | E10: -0.0135 | F10: 0.0384 | G10: -0.0312 | H10: -0.0011 | J10: Best and Worst Asset Per Stress Period
B11: 43466 | C11: -0.0029 | D11: 0.005 | E11: 0.0733 | F11: 0.0474 | G11: 0.0153 | H11: 0.02 | J11: Stress Period | K11: Best Asset | L11: Return | M11: Worst Asset | N11: Return
B12: 43497 | C12: -0.0036 | D12: -0.0185 | E12: 0.015 | F12: 0.0052 | G12: 0.0144 | H12: -0.0017 | J12: 2016 Demonetisation | K12: NIFTY Bank | L12: =MAX(K4:P4) -> 0.1001 | M12: Gold | N12: =MIN(M4:R4) -> -0.0604
B13: 43525 | C13: 0.077 | D13: 0.1358 | E13: -0.0066 | F13: -0.0482 | G13: -0.0323 | H13: -0.0233 | J13: 2018 IL&FS | K13: NIFTY Bank | L13: =MAX(K5:P5) -> 0.0979 | M13: Bonds | N13: =MIN(K5:P5) -> -0.0772
A14: 2020 COVID | B14: 43862 | C14: -0.0636 | D14: -0.0547 | E14: -0.0577 | F14: 0.0418 | G14: -0.0346 | H14: 0.0139 | J14: 2020 COVID | K14: Gold | L14: =MAX(K6:P6) -> 0.2489 | M14: NIFTY Bank | N14: =MIN(K6:P6) -> -0.1592
B15: 43891 | C15: -0.2325 | D15: -0.3432 | E15: -0.161 | F15: 0.0225 | G15: -0.0366 | H15: 0.0386 | J15: 2022 Rate Hikes | K15: NIFTY Bank | L15: =MAX(K7:P7) -> 0.122 | M15: NIFTY IT | N15: =MIN(K7:P7) -> -0.1075
B16: 43922 | C16: 0.1468 | D16: 0.1249 | E16: 0.1054 | F16: 0.1141 | G16: -0.0046 | H16: -0.0034
B17: 43952 | C17: -0.0284 | D17: -0.1039 | E17: -0.0069 | F17: -0.0371 | G17: -0.0159 | H17: 0.0068
B18: 43983 | C18: 0.0753 | D18: 0.1074 | E18: 0.0531 | F18: 0.0395 | G18: -0.0208 | H18: -0.0007
B19: 44013 | C19: 0.0749 | D19: 0.0126 | E19: 0.2249 | F19: 0.1063 | G19: -0.0087 | H19: -0.0083
B20: 44044 | C20: 0.0284 | D20: 0.0977 | E20: -0.0079 | F20: -0.0382 | G20: 0.0413 | H20: -0.0222
A21: 2022 RATE HIKES | B21: 44621 | C21: 0.0399 | D21: 0.0046 | E21: 0.073 | F21: 0.0122 | G21: 0.0108 | H21: 0.0054
B22: 44652 | C22: -0.0207 | D22: -0.0078 | E22: -0.1293 | F22: 0.0152 | G22: 0.0433 | H22: 0.0082
B23: 44682 | C23: -0.0303 | D23: -0.0166 | E23: -0.0615 | F23: -0.0188 | G23: 0.0387 | H23: 0.0137
B24: 44713 | C24: -0.0485 | D24: -0.0581 | E24: -0.0619 | F24: -0.0043 | G24: 0.0047 | H24: 0.0178
B25: 44743 | C25: 0.0873 | D25: 0.1217 | E25: 0.047 | F25: 0.0069 | G25: -0.0174 | H25: 0.0049
B26: 44774 | C26: 0.035 | D26: 0.0546 | E26: -0.0255 | F26: -0.0036 | G26: -0.018 | H26: 0.002
B27: 44805 | C27: -0.0374 | D27: -0.0229 | E27: -0.0502 | F27: -0.0169 | G27: 0.0292 | H27: 0.0254
B28: 44835 | C28: 0.0537 | D28: 0.0693 | E28: 0.0647 | F28: 0.0016 | G28: 0.0064 | H28: 0.0155
B29: 44866 | C29: 0.0414 | D29: 0.0466 | E29: 0.0579 | F29: 0.0433 | G29: -0.0222 | H29: -0.017
B30: 44896 | C30: -0.0348 | D30: -0.0057 | E30: -0.0582 | F30: 0.0375 | G30: 0.0065 | H30: 0.0167
B31: 44927 | C31: -0.0245 | D31: -0.0542 | E31: 0.0391 | F31: 0.0402 | G31: 0.0022 | H31: -0.0118
B32: 44958 | C32: -0.0203 | D32: -0.0095 | E32: -0.0026 | F32: -0.0259 | G32: 0.0155 | H32: 0.011

Sheet Portfolio Allocation
A1: Score_Min | B1: Score_Max | C1: Signal | E1: Asset | F1: Green | G1: Amber | H1: Red | J1: Transition | K1: Nifty 50 | L1: Nifty Bank | M1: Nifty IT | N1: Gold | O1: Bonds | P1: USD/INR
A2: 0 | B2: 4 | C2: Green | E2: NIFTY 50 | F2: 0.35 | G2: 0.3 | H2: 0.15 | J2: Green → Amber | K2: -0.1 | L2: -0.07 | M2: -0.02 | N2: 0.05 | O2: 0.12 | P2: 0.02
A3: 4.01 | B3: 6 | C3: Amber | E3: NIFTY Bank | F3: 0.15 | G3: 0.12 | H3: 0.03 | J3: Amber → Red | K3: -0.1 | L3: -0.05 | M3: -0.01 | N3: 0.05 | O3: 0.11 | P3: 0
A4: 6.01 | B4: 10 | C4: Red | E4: NIFTY IT | F4: 0.1 | G4: 0.09 | H4: 0.07 | J4: Red → Amber | K4: 0.1 | L4: 0.05 | M4: 0.01 | N4: -0.05 | O4: -0.11 | P4: 0
E5: Gold | F5: 0.15 | G5: 0.17 | H5: 0.33 | J5: Amber → Green | K5: 0.1 | L5: 0.07 | M5: 0.02 | N5: -0.05 | O5: -0.12 | P5: -0.02
E6: Bonds | F6: 0.2 | G6: 0.25 | H6: 0.35
E7: USD/INR | F7: 0.05 | G7: 0.07 | H7: 0.07

Sheet Backtesting
A1: DATE | B1: EWS SIGNAL | C1: Actual Portfolio Return | D1: EWS Adjusted Portfolio Return | E1: Cumulative Actual Return | F1: Cumulative EWS Return
A2: 41760 | B2: ='Risk Score'!F2 -> Amber | C2: =(Assets!C3*0.35)+(Assets!E3*0.15)+(Assets!G3*0.1)+(Assets!J3*0.05)+(Assets!L3*0.2)+(Assets!N3*0.05) -> 0.03734 | D2: =IF(B2="Green", (Assets!C3*0.35)+(Assets!E3*0.15)+(Assets!G3*0.1)+(Assets!J3*0.15)+(Assets!L3*0.2)+(Assets!N3*0.05), IF(B2="Amber", (Assets!C3*0.3)+(Assets!E3*0.12)+(Assets!G3*0.09)+(Assets!J3*0.17)+(Assets!L3*0.25)+(Assets!N3*0.07), (Assets!C3*0.15)+(Assets!E3*0.03)+(Assets!G3*0.07)+(Assets!J3*0.33)+(Assets!L3*0.35)+(Assets!N3*0.07))) -> 0.015046 | E2: =1+C2 -> 1.03734 | F2: =1+D2 -> 1.015046
A3: 41791 | B3: ='Risk Score'!F3 -> Green | C3: =(Assets!C4*0.35)+(Assets!E4*0.15)+(Assets!G4*0.1)+(Assets!J4*0.05)+(Assets!L4*0.2)+(Assets!N4*0.05) -> 0.038855 | D3: =IF(B3="Green", (Assets!C4*0.35)+(Assets!E4*0.15)+(Assets!G4*0.1)+(Assets!J4*0.15)+(Assets!L4*0.2)+(Assets!N4*0.05), IF(B3="Amber", (Assets!C4*0.3)+(Assets!E4*0.12)+(Assets!G4*0.09)+(Assets!J4*0.17)+(Assets!L4*0.25)+(Assets!N4*0.07), (Assets!C4*0.15)+(Assets!E4*0.03)+(Assets!G4*0.07)+(Assets!J4*0.33)+(Assets!L4*0.35)+(Assets!N4*0.07))) -> 0.043455 | E3: =E2*(1+C3) -> 1.0776458 | F3: =F2*(1+D3) -> 1.0591548
A4: 41821 | B4: ='Risk Score'!F4 -> Green | C4: =(Assets!C5*0.35)+(Assets!E5*0.15)+(Assets!G5*0.1)+(Assets!J5*0.05)+(Assets!L5*0.2)+(Assets!N5*0.05) -> 0.008355 | D4: =IF(B4="Green", (Assets!C5*0.35)+(Assets!E5*0.15)+(Assets!G5*0.1)+(Assets!J5*0.15)+(Assets!L5*0.2)+(Assets!N5*0.05), IF(B4="Amber", (Assets!C5*0.3)+(Assets!E5*0.12)+(Assets!G5*0.09)+(Assets!J5*0.17)+(Assets!L5*0.25)+(Assets!N5*0.07), (Assets!C5*0.15)+(Assets!E5*0.03)+(Assets!G5*0.07)+(Assets!J5*0.33)+(Assets!L5*0.35)+(Assets!N5*0.07))) -> 0.006915 | E4: =E3*(1+C4) -> 1.0866496 | F4: =F3*(1+D4) -> 1.0664789 | H4: SIGNAL COUNT
A5: 41852 | B5: ='Risk Score'!F5 -> Green | C5: =(Assets!C6*0.35)+(Assets!E6*0.15)+(Assets!G6*0.1)+(Assets!J6*0.05)+(Assets!L6*0.2)+(Assets!N6*0.05) -> 0.015215 | D5: =IF(B5="Green", (Assets!C6*0.35)+(Assets!E6*0.15)+(Assets!G6*0.1)+(Assets!J6*0.15)+(Assets!L6*0.2)+(Assets!N6*0.05), IF(B5="Amber", (Assets!C6*0.3)+(Assets!E6*0.12)+(Assets!G6*0.09)+(Assets!J6*0.17)+(Assets!L6*0.25)+(Assets!N6*0.07), (Assets!C6*0.15)+(Assets!E6*0.03)+(Assets!G6*0.07)+(Assets!J6*0.33)+(Assets!L6*0.35)+(Assets!N6*0.07))) -> 0.015275 | E5: =E4*(1+C5) -> 1.103183 | F5: =F4*(1+D5) -> 1.0827693 | H5: Green | I5: =COUNTIF(B2:B120,"green") -> 100
A6: 41883 | B6: ='Risk Score'!F6 -> Green | C6: =(Assets!C7*0.35)+(Assets!E7*0.15)+(Assets!G7*0.1)+(Assets!J7*0.05)+(Assets!L7*0.2)+(Assets!N7*0.05) -> 0.00106 | D6: =IF(B6="Green", (Assets!C7*0.35)+(Assets!E7*0.15)+(Assets!G7*0.1)+(Assets!J7*0.15)+(Assets!L7*0.2)+(Assets!N7*0.05), IF(B6="Amber", (Assets!C7*0.3)+(Assets!E7*0.12)+(Assets!G7*0.09)+(Assets!J7*0.17)+(Assets!L7*0.25)+(Assets!N7*0.07), (Assets!C7*0.15)+(Assets!E7*0.03)+(Assets!G7*0.07)+(Assets!J7*0.33)+(Assets!L7*0.35)+(Assets!N7*0.07))) -> -0.00287 | E6: =E5*(1+C6) -> 1.1043523 | F6: =F5*(1+D6) -> 1.0796618 | H6: Amber | I6: =COUNTIF(B:B,"amber") -> 15
A7: 41913 | B7: ='Risk Score'!F7 -> Green | C7: =(Assets!C8*0.35)+(Assets!E8*0.15)+(Assets!G8*0.1)+(Assets!J8*0.05)+(Assets!L8*0.2)+(Assets!N8*0.05) -> 0.02539 | D7: =IF(B7="Green", (Assets!C8*0.35)+(Assets!E8*0.15)+(Assets!G8*0.1)+(Assets!J8*0.15)+(Assets!L8*0.2)+(Assets!N8*0.05), IF(B7="Amber", (Assets!C8*0.3)+(Assets!E8*0.12)+(Assets!G8*0.09)+(Assets!J8*0.17)+(Assets!L8*0.25)+(Assets!N8*0.07), (Assets!C8*0.15)+(Assets!E8*0.03)+(Assets!G8*0.07)+(Assets!J8*0.33)+(Assets!L8*0.35)+(Assets!N8*0.07))) -> 0.02366 | E7: =E6*(1+C7) -> 1.1323918 | F7: =F6*(1+D7) -> 1.1052066 | H7: Red | I7: =COUNTIF(B:B,"red") -> 4
A8: 41944 | B8: ='Risk Score'!F8 -> Green | C8: =(Assets!C9*0.35)+(Assets!E9*0.15)+(Assets!G9*0.1)+(Assets!J9*0.05)+(Assets!L9*0.2)+(Assets!N9*0.05) -> 0.02539 | D8: =IF(B8="Green", (Assets!C9*0.35)+(Assets!E9*0.15)+(Assets!G9*0.1)+(Assets!J9*0.15)+(Assets!L9*0.2)+(Assets!N9*0.05), IF(B8="Amber", (Assets!C9*0.3)+(Assets!E9*0.12)+(Assets!G9*0.09)+(Assets!J9*0.17)+(Assets!L9*0.25)+(Assets!N9*0.07), (Assets!C9*0.15)+(Assets!E9*0.03)+(Assets!G9*0.07)+(Assets!J9*0.33)+(Assets!L9*0.35)+(Assets!N9*0.07))) -> 0.02605 | E8: =E7*(1+C8) -> 1.1611433 | F8: =F7*(1+D8) -> 1.1339972
A9: 41974 | B9: ='Risk Score'!F9 -> Green | C9: =(Assets!C10*0.35)+(Assets!E10*0.15)+(Assets!G10*0.1)+(Assets!J10*0.05)+(Assets!L10*0.2)+(Assets!N10*0.05) -> -0.02101 | D9: =IF(B9="Green", (Assets!C10*0.35)+(Assets!E10*0.15)+(Assets!G10*0.1)+(Assets!J10*0.15)+(Assets!L10*0.2)+(Assets!N10*0.05), IF(B9="Amber", (Assets!C10*0.3)+(Assets!E10*0.12)+(Assets!G10*0.09)+(Assets!J10*0.17)+(Assets!L10*0.25)+(Assets!N10*0.07), (Assets!C10*0.15)+(Assets!E10*0.03)+(Assets!G10*0.07)+(Assets!J10*0.33)+(Assets!L10*0.35)+(Assets!N10*0.07))) -> -0.02014 | E9: =E8*(1+C9) -> 1.1367476 | F9: =F8*(1+D9) -> 1.1111585 | H9: Actual Portfolio Return
